Workbook

Sheet Sheet1
A1: Username | B1: Name | C1: Direct Permission Sets | D1: User License | E1: Profile | F1: Role | G1: Manager | H1: Title | I1: Company | J1: Direct Permission Set Count | L1: Permission Set Group Count | N1: Direct Permission Set Source
A2: areid@probomedical.com | B2: Aaliyah Reid | C2: "Super User"; Access to purchasing fields but not creating opps; Add Asset Page; Add Product Page; All Account Fields; Change Account Owner; Create Item Receipts; Create new assets; Create Purchasing Opps; Creating Price Books; Edit Loaner Fields; Endoscopy Test/Repair Permission Set; Executive Power; Full access to evaluations; Full access to work orders; IR PR PO Bill Permissions; Loaner Assets Object; Loaner Object; PandaDoc Access; Pandadoc Object Permissions; Print Shipping Checklist Button; Product Test Page Tab Visibility; Purchasing Fields; Purchasing Opportunity Item Receipts; Sales Opp; Sales Opportunity Access; Ship to Account Opp; Shipping Account Number - Opps; Shipping/Receiving; Trisonics User; UK Admin Permission Set; Uncheck reserve box; Work Order Line Items; Work Order Shipping - Sales Ops; Zenkraft - Full Access | D2: Salesforce | E2: Sales Manager | H2: Customer Service Temp | I2: Probo Medical | J2: =COUNTIF('Direct Permission Sets'!$B$2:$B$7222,A2) | N2: Added from ProboMedical SOQL export. Rows: 7221. Assignment Source = Direct Permission Set, excluding profile-owned permission sets and permission set group assignments.
A3: aposton@probomedical.com | B3: Aaron Poston | C3: Add Asset Page; Add Product Page; All Account Fields; All RMA Fields; Asset and Product Analytics Modify All; Change Record Type RMA; Change RMA action; Cold Storage - Warehouse Reps; Create and Edit Purchasing Returns; Create Item Receipts; Create new assets; Create Products; Creating New Products; Delete RMAs; Edit Serial# on Assets; Handle Assets; Intercompany Transfer Opportunities; Intercompany Transfers Object; IR PR PO Bill Permissions; Loaner Assets Object; Loaner Object; PandaDoc Access; Pandadoc Object Permissions; Parts Operations; Parts Product Name Field; Print Shipping Checklist Button; Product Repair Access; Product Test; Reports and Dashboards; RMA Action (without approval permissions); RMA on Evaluations; Shipping Account Number - Opps; Shipping Cost; Shipping Team; Shipping/Receiving; Sold; Work Order Line Items; Work Order Shipping - Sales Ops; Zenkraft - Admin; Zenkraft - Full Access; Zenkraft - Read Only; Zenkraft - Read-Only User; Zenkraft - Standard User | D3: Salesforce | E3: QC Manager | F3: Ops Manager | I3: AlphaSource Group | J3: =COUNTIF('Direct Permission Sets'!$B$2:$B$7222,A3)
A4: adam.brzostowski@probomedical.co.uk | B4: Adam Brzostowski | C4: Field Service Mobile License; Field Service Resource License; Field Service Resource Permissions; Flow User; Lead Access - FSL Tech (Can Create Leads); Product Analytics and Asset Permissions | D4: Salesforce | E4: Engineer - UK | F4: Engineer - UK | G4: Adam Ward | H4: Senior Engineer | J4: =COUNTIF('Direct Permission Sets'!$B$2:$B$7222,A4)
A5: amorris1@probomedical.com | B5: Adam Morris | C5: Field Service Mobile License; Field Service Resource License; Field Service Resource Permissions; Flow User; FSL Create Lead Perms; FSR Attached; US FSL V1 Perm | D5: Salesforce | E5: FSL US | G5: Hobie Sears | J5: =COUNTIF('Direct Permission Sets'!$B$2:$B$7222,A5)
A6: amorris@probomedical.com | B6: Adam Morris | D6: Customer Community Plus | E6: FSE Portal | F6: Probo Medical - Portal Customer User | H6: FSE | J6: =COUNTIF('Direct Permission Sets'!$B$2:$B$7222,A6)
A7: awalter@probomedical.com | B7: Adam Walter | C7: Add Asset Page; Add Product Page; All Record Types; Create external repairs; Edit cost fields; Full access to evaluations; Invoice Permissions; Loaner Assets Object; Loaner Object; Reports and Dashboards; RMA action and approval permissions; Service Contract Management; Switch to Lightning; SWO/HWO; Two Factor Authentication Required; View Customer Satisfaction Surveys; Warranty claims and products; Zenkraft - Admin | D7: Salesforce | E7: System Administrator Custom | F7: Business Development Manager | I7: Probo Medical, Inc. | J7: =COUNTIF('Direct Permission Sets'!$B$2:$B$7222,A7)
A8: awalter@guest.probomedical.com | B8: Adam Walter | D8: Customer Community Plus | E8: Oncura Portal | F8: Oncura Partners Customer Manager | I8: Probo Medical, Inc. | J8: =COUNTIF('Direct Permission Sets'!$B$2:$B$7222,A8)
A9: adam.ward@probomedical.co.uk | B9: Adam Ward | C9: Add Asset Page; Add Product Page; Create Products; Creating New Products; Edit CLI Peripheral, Service Network, and Service Hardware and Software Fields; Edit Opportunities; Edit Product Status; Field Service Dispatcher License; Field Service Dispatcher Permissions; Field Service Mobile License; Field Service Resource License; Field Service Resource Permissions; Flow User; Handle Assets; Lead Access - FSL Tech (Can Create Leads); PandaDoc Access; Pandadoc Object Permissions; Product Analytics and Asset Permissions; Sales Opportunity Access; Service Contract Management; SWO/HWO | D9: Salesforce | E9: Commercial Manager - UK | F9: Manager - UK | G9: Tom Meredith | J9: =COUNTIF('Direct Permission Sets'!$B$2:$B$7222,A9)
A10: azanga@probomedical.com | B10: Aidan Zanga | C10: Access to harvest work orders; Add Asset Page; Add Product Page; All Record Types; AP Page - Cost; Asset Cost; Check repair information; Create new assets; Edit Ratings Object; Edit Ratings/Notes on Asset Page; Edit review status; Edit Serial# on Assets; Export Reports; Functional Rating for Parts; Loaner Assets Object; Loaner Object; Move Location Enabled; Part Tests and Repairs; Parts Operations; Parts Record Type; Product Test; Product Test Edit; Purchase Approval Checkbox; Reports and Dashboards; Systems Test; Two Factor Authentication Required | D10: Salesforce | E10: QC Manager | H10: Component Repair Engineer | I10: Probo Medical, Inc. | J10: =COUNTIF('Direct Permission Sets'!$B$2:$B$7222,A10)
A11: amirko@proborestoration.com | B11: Alex Mirko | C11: Flow User | D11: Salesforce | E11: Mechanical Services | J11: =COUNTIF('Direct Permission Sets'!$B$2:$B$7222,A11)
A12: apogrebinsky@probomedical.com | B12: Alex Pogrebinsky | C12: Access to harvest work orders; Add Asset Page; Add Product Page; All Record Types; All RMA Fields; Asset and Product Analytics Modify All; Asset2- Review Status; Create new assets; Creating New Products; Creating Price Books; Edit Ratings/Notes on Asset Page; PandaDoc Access; Pandadoc Object Permissions; Parts Operations; Parts Record Type; Print Shipping Checklist Button; Product Test; Repairable Fields; Shipping Team; Shipping/Receiving | D12: Salesforce | E12: QC Manager | F12: Ops Tech | I12: AlphaSource Group | J12: =COUNTIF('Direct Permission Sets'!$B$2:$B$7222,A12)
A13: adamato@probomedical.com | B13: Alexus D'Amato | C13: Add Asset Page; Add Product Page; Cold Storage - Invoicing; Cold Storage - Warehouse Reps; Location Unlocked; Move Location Enabled; PandaDoc Access; Pandadoc Object Permissions; Training Class/Class Attendance Access | D13: Salesforce | E13: Sales Manager | H13: Project Coordinator | I13: AlphaSource Group | J13: =COUNTIF('Direct Permission Sets'!$B$2:$B$7222,A13)
A14: alfie.john@probomedical.co.uk | B14: Alfie John | C14: Chargent User (Base); Chargent User (Orders); Flow User; Invoice Permissions; Manage Intacct Synced Records; PandaDoc Access; Pandadoc Object Permissions; Physical Location on Invoice Object; Product Analytics and Asset Permissions | D14: Salesforce | E14: Commercial Finance - UK | H14: European Accounts Payable Assistant | I14: Probo Medical, Ltd. | J14: =COUNTIF('Direct Permission Sets'!$B$2:$B$7222,A14)
A15: aekizian@probomedical.com | B15: Aline Ekizian | C15: Add Asset Page; Add Product Page; PandaDoc Access; Pandadoc Object Permissions | D15: Salesforce | E15: Sales Manager | F15: Sales Manager | G15: Dur Thomason | H15: Director, Enterprise Sales - West | I15: Probo Medical | J15: =COUNTIF('Direct Permission Sets'!$B$2:$B$7222,A15)
A16: alison.williams@probomedical.co.uk | B16: Alison Williams | C16: Access to Product & Repair Pricing; Access to purchasing fields but not creating opps; Add Asset Page; Add Product Page; All RMA Fields; Create Item Receipts; Create new assets; Create Purchasing Opps; Field Service Dispatcher License; Field Service Dispatcher Permissions; Flow User; Pandadoc Object Permissions; Product Analytics and Asset Permissions; Purchasing Fields | D16: Salesforce | E16: Commercial Sales - UK | F16: Manager - UK | G16: Tom Meredith | H16: Large Equipment Service Coordinator | I16: Probo Medical, Ltd. | J16: =COUNTIF('Direct Permission Sets'!$B$2:$B$7222,A16)
A17: alpha_source@ultrasoundrepair.force.com | B17: Alpha Source Site Guest User | D17: Guest User License | E17: Alpha Source Profile | J17: =COUNTIF('Direct Permission Sets'!$B$2:$B$7222,A17)
A18: ahaley@probomedical.com | B18: Alyssa Haley | C18: Add Asset Page; Add Product Page; PandaDoc Access; Pandadoc Object Permissions | D18: Salesforce | E18: Sales User | F18: Sales Rep | H18: Veterinary Ultrasound Sales Manager | I18: Probo Medical, Inc. | J18: =COUNTIF('Direct Permission Sets'!$B$2:$B$7222,A18)
A19: avondrach@probomedical.com | B19: Alyssa VonDrach | C19: Add Product Page; All Record Types; All RMA Fields; Asset and Product Analytics Modify All; Asset2- Review Status; Big Iron Opportunity Type; Change Opportunity Owner; Create new assets; Create Purchasing Opps; Creating New Products; Credit Memo- View Access; Delete RMAs; Deleting/Merging Accounts; Field Service Dispatcher Permissions; Field Service Mobile License; Field Service Resource License; Intercompany Transfer Opportunities; Intercompany Transfers Object; Invoice Permissions; IR PR PO Bill Permissions; Loaner Assets Object; Loaner Object; Loaner Turned Exchange; Manage Assets; Manage Billing Address on Intacct Synced Account; Opportunity - Delete Records; PandaDoc Access; Pandadoc Object Permissions; Product Dealer Pricing; Purchasing Fields; Record Types- Harrisburg Sales; Reports and Dashboards; Sales Opportunity Access; Service Contract Management; Shipping Cost; Shipping/Receiving; Switch to Lightning; SWO/HWO; Total Cost of Assets; Trisonics User; Vendor Sourcing; Vendor Sourcing Full Access; Work Order Shipping - Sales Ops; Zenkraft - Read Only; Zenkraft - Standard User | D19: Salesforce | E19: Sales User | F19: Sales Rep | I19: Probo Medical, Inc. | J19: =COUNTIF('Direct Permission Sets'!$B$2:$B$7222,A19)
A20: aboyko@probomedical.com | B20: Amanda Boyko | C20: Add Asset Page; Add Product Page; PandaDoc Access; Pandadoc Object Permissions | D20: Salesforce | E20: Sales User | H20: Sales | I20: Probo Medical, Inc | J20: =COUNTIF('Direct Permission Sets'!$B$2:$B$7222,A20)
A21: ahironimus@probomedical.com | B21: Amber Hironimus | C21: Add Asset Page; Add Product Page; All Record Types; All RMA Fields; ApprovalForm access; Asset and Product Analytics Modify All; Asset Cost; Asset2- Review Status; Big Iron Opportunity Type; Certain Asset Fields; Change Opportunity Owner; Change Record Type RMA; Create new assets; Create Warranty Ops; Creating New Products; Credit Memo- View Access; Delete RMAs; Deleting/Merging Accounts; Edit cost fields; Edit review status; Edit Serial# on Assets; Field Service Dispatcher Permissions; Field Service Mobile License; Field Service Resource License; Field Service Resource Permissions; FieldServiceMobileStandardPermSetUS; Flow User; Intercompany Transfer Opportunities; Invoice Permissions; IR PR PO Bill Permissions; Loaner Assets Object; Loaner Object; Loaner Turned Exchange; Manage Assets; Manage Billing Address on Intacct Synced Account; Move Location Enabled; Non-Conforming Record Access; Opportunity - Delete Records; PandaDoc Access; Pandadoc Object Permissions; Product Dealer Pricing; Purchasing Fields; Record Types- Harrisburg Sales; Reports and Dashboards; RMA on Evaluations; Sales Opportunity Access; Service Contract Management; Shipping Cost; Switch to Lightning; SWO/HWO; Trisonics User; Two Factor Authentication Required; Uncheck reserve box; US FSL V1 Perm; Vendor Sourcing; Vendor Sourcing Full Access; Work Order Shipping - Sales Ops; Zenkraft - Read Only; Zenkraft - Standard User | D21: Salesforce | E21: Sales Manager | I21: Probo Medical, Inc. | J21: =COUNTIF('Direct Permission Sets'!$B$2:$B$7222,A21)
A22: amy.sharp@probomedical.co.uk | B22: Amy Sharp | C22: Add Product Page; Change Invoice Number on Opp; Chargent User (Base); Chargent User (Orders); Invoice Permissions; Manage Billing Address on Intacct Synced Account; Manage Intacct Synced Records; Manage Payment Terms, Credit Limit on Intacct Synced Account; PandaDoc Access; Pandadoc Object Permissions; Physical Location on Invoice Object; Product Analytics and Asset Permissions | D22: Salesforce | E22: Commercial Finance - UK | G22: Tina Betts | H22: European Accounting Coordinator | I22: Probo Medical, Ltd. | J22: =COUNTIF('Direct Permission Sets'!$B$2:$B$7222,A22)
A23: ahoward@probomedical.com | B23: Ana Howard | C23: Add Product Page; All Record Types; Asset and Product Analytics Modify All; Loaner Assets Object; Loaner Object; Modify All - Assets; SWO/HWO; Two Factor Authentication Required | D23: Salesforce | E23: Repair Tech | I23: Probo Medical, Inc. | J23: =COUNTIF('Direct Permission Sets'!$B$2:$B$7222,A23)
A24: aserrano@probomedical.com | B24: Ana Serrano | C24: Add Asset Page; Add Product Page; All Record Types; AP Page - Cost; Asset Cost; Big Iron Opportunity Type; Chargent Payment Console; Chargent Payment Request; Chargent Terminal Unlinked Payments; Chargent Terminal User; Chargent User (Base); Chargent User (Orders); IR PR PO Bill Permissions; Loaner Assets Object; Manage Intacct Synced Records; Pandadoc Object Permissions; Reports and Dashboards; Return from Sale RMA; SWO/HWO | D24: Salesforce | E24: Accounting | I24: Probo Medical, Inc. | J24: =COUNTIF('Direct Permission Sets'!$B$2:$B$7222,A24)
A25: aisley@probomedical.com | B25: Andrea Isley | C25: Add Asset Page; Add Product Page; Asset Reserved Checkbox; Lead Owner Change; Marketing - Lead Assignment; PandaDoc Access; Pandadoc Object Permissions | D25: Salesforce | E25: Sales Manager | J25: =COUNTIF('Direct Permission Sets'!$B$2:$B$7222,A25)
A26: andreea.dura@probomedical.co.uk | B26: Andreea Dura | C26: Change Account Owner; Field Service Guest User Permissions; PandaDoc Access; Pandadoc Object Permissions; Product Analytics and Asset Permissions | D26: Salesforce | E26: Commercial Sales - UK | F26: Manager - UK | G26: Lee Moger | H26: Account Manager | I26: Probo Medical Ltd. | J26: =COUNTIF('Direct Permission Sets'!$B$2:$B$7222,A26)
A27: acarvajal@probomedical.com | B27: Andres Carvajal | C27: Add Asset Page; Add Product Page; All Record Types; Check repair information; Edit Public Reports; Export Reports; Functional Rating for Parts; Loaner Assets Object; Loaner Object; Location Unlocked; Part Tests and Repairs; Parts Operations; Parts Record Type; Product Test; Product Test Edit; Refurb Test & Refurb Part Request Permissions; Repairable Fields; Reports and Dashboards; Systems Test; Two Factor Authentication Required | D27: Salesforce | E27: QC Manager | H27: Diagnostic Engineer | I27: Probo Medical, Inc. | J27: =COUNTIF('Direct Permission Sets'!$B$2:$B$7222,A27)
A28: andrew.fairley@probomedical.co.uk | B28: Andrew Fairley | C28: Field Service Mobile License; Field Service Resource License; Field Service Resource Permissions; Flow User; Lead Access - FSL Tech (Can Create Leads); Product Analytics and Asset Permissions | D28: Salesforce | E28: Engineer - UK | F28: Engineer - UK | G28: Chris Dall-Smith | H28: Senior Engineer | J28: =COUNTIF('Direct Permission Sets'!$B$2:$B$7222,A28)
A29: ajaystewart@probomedical.com | B29: Andrew Jay Stewart | D29: Customer Community Plus | E29: FSE Portal | F29: Probo Medical - Portal Customer User | H29: FSE | I29: Probo Medical, Inc. | J29: =COUNTIF('Direct Permission Sets'!$B$2:$B$7222,A29)
A30: ajaystewart1@probomedical.com | B30: Andrew Jay Stewart | C30: Asset and Product Analytics Modify All; Field Service Mobile License; Field Service Resource License; Field Service Resource Permissions; Flow User; FSL Create Lead Perms; FSR Attached; Lead Access - FSL Tech (Can Create Leads); US FSL V1 Perm | D30: Salesforce | E30: FSL US | G30: Brad Lawson | J30: =COUNTIF('Direct Permission Sets'!$B$2:$B$7222,A30)
A31: andrew.murdoch@probomedical.co.uk | B31: Andrew Murdoch | C31: Field Service Mobile License; Field Service Resource License; Field Service Resource Permissions; Flow User; Lead Access - FSL Tech (Can Create Leads) | D31: Salesforce | E31: Engineer - UK | G31: Chris Dall-Smith | H31: Service Engineer | J31: =COUNTIF('Direct Permission Sets'!$B$2:$B$7222,A31)
A32: andrew.wiltshire@probomedical.co.uk | B32: Andrew Wiltshire | C32: Field Service Mobile License; Field Service Resource License; Field Service Resource Permissions; Flow User; Lead Access - FSL Tech (Can Create Leads); Product Analytics and Asset Permissions | D32: Salesforce | E32: Engineer - UK | G32: Chris Dall-Smith | H32: Senior Engineer | J32: =COUNTIF('Direct Permission Sets'!$B$2:$B$7222,A32)
A33: andy.woodhouse@probomedical.co.uk | B33: Andy Woodhouse | C33: Field Service Mobile License; Field Service Resource License; Field Service Resource Permissions; Flow User; Lead Access - FSL Tech (Can Create Leads); Product Analytics and Asset Permissions | D33: Salesforce | E33: Engineer - UK | F33: Engineer - UK | G33: Chris Dall-Smith | H33: Senior Field Service Engineer | J33: =COUNTIF('Direct Permission Sets'!$B$2:$B$7222,A33)
A34: abates@probomedical.com | B34: Angel Bates | C34: Access to accounting info; Add Asset Page; Add Product Page; All Account Fields; Change Account Owner; Credit Memo Permission Set; Credit Memo- View Access; IR PR PO Bill Permissions; Manage Intacct Synced Records; PandaDoc Access; Pandadoc Object Permissions; Ship to Account Opp; Shipping Account Number - Opps | D34: Salesforce | E34: Accounting + Sales | H34: ASG Credit/Collections | I34: AlphaSource Group | J34: =COUNTIF('Direct Permission Sets'!$B$2:$B$7222,A34)
A35: aficuciello1@probomedical.com | B35: Anthony Ficuciello | C35: Field Service Mobile License; Field Service Resource License; Field Service Resource Permissions; Flow User; FSL Create Lead Perms; FSR Attached; Lead Access - FSL Tech (Can Create Leads); US FSL V1 Perm | D35: Salesforce | E35: FSL US | G35: Brad Lawson | J35: =COUNTIF('Direct Permission Sets'!$B$2:$B$7222,A35)
A36: aficuciello@probomedical.com | B36: Anthony Ficuciello | D36: Customer Community Plus | E36: FSE Portal | F36: Probo Medical - Portal Customer User | H36: FSE | I36: Probo Medical, Inc. | J36: =COUNTIF('Direct Permission Sets'!$B$2:$B$7222,A36)
A37: awhitsit@probomedical.com | B37: Anthony Whitsit | C37: Asset and Product Analytics Modify All; Creating New Products; Loaner Assets Object; Loaner Object; Modify All - Assets; Print Shipping Checklist Button; Product Repair Access; Product Test; Product Test Edit; Shipping Account Number - Opps; Shipping Team; Shipping/Receiving; Unable to further improve - cosmetic; Unable to further improve - functional and cosmetic; Zenkraft - Full Access; Zenkraft - Read Only; Zenkraft - Standard User | D37: Salesforce | E37: Repair Tech Lead | F37: Ops Tech | J37: =COUNTIF('Direct Permission Sets'!$B$2:$B$7222,A37)
A38: areed@probomedical.com | B38: Anton Reed | C38: Add Product Page; All Record Types; Asset and Product Analytics Modify All; Loaner Assets Object; Loaner Object; Modify All - Assets; SWO/HWO; Two Factor Authentication Required; Unable to further improve - cosmetic | D38: Salesforce | E38: Repair Tech | I38: Probo Medical, Inc. | J38: =COUNTIF('Direct Permission Sets'!$B$2:$B$7222,A38)
A39: approval_attachment@probomedical.force.com | B39: Approval Attachment Site Guest User | C39: Approval Form Guest Access | D39: Guest User License | E39: Approval Attachment Profile | I39: Probo Medical, Inc. | J39: =COUNTIF('Direct Permission Sets'!$B$2:$B$7222,A39)
A40: approval_form@probomedical.force.com | B40: Approval Form Site Guest User | C40: Approval Form Guest Access | D40: Guest User License | E40: Approval Form Profile | J40: =COUNTIF('Direct Permission Sets'!$B$2:$B$7222,A40)
...

Sheet Direct Permission Sets
A1: User Name | B1: Username | C1: Email | D1: User Type | E1: Profile | F1: Permission Set Label | G1: Permission Set API Name | H1: Permission Set Type | I1: Modify All Data | J1: View All Data | K1: Assignment Source | L1: User Id | M1: Permission Set Id
A2: Aaliyah Reid | B2: areid@probomedical.com | C2: areid@probomedical.com | D2: Standard | E2: Sales Manager | F2: "Super User" | G2: Super_User | H2: Regular | I2: TRUE | J2: TRUE | K2: Direct Permission Set | L2: 005Ro00000G5TJVIA3 | M2: 0PS4O000000vMZBWA2
A3: Aaliyah Reid | B3: areid@probomedical.com | C3: areid@probomedical.com | D3: Standard | E3: Sales Manager | F3: Access to purchasing fields but not creating opps | G3: Access_to_purchasing_fields_but_not_creating_opps | H3: Regular | I3: FALSE | J3: FALSE | K3: Direct Permission Set | L3: 005Ro00000G5TJVIA3 | M3: 0PS0B000000b6U4WAI
A4: Aaliyah Reid | B4: areid@probomedical.com | C4: areid@probomedical.com | D4: Standard | E4: Sales Manager | F4: Add Asset Page | G4: Add_Asset_Page | H4: Regular | I4: FALSE | J4: FALSE | K4: Direct Permission Set | L4: 005Ro00000G5TJVIA3 | M4: 0PS4O000000zpzaWAA
A5: Aaliyah Reid | B5: areid@probomedical.com | C5: areid@probomedical.com | D5: Standard | E5: Sales Manager | F5: Add Product Page | G5: Add_Product_Page | H5: Regular | I5: FALSE | J5: FALSE | K5: Direct Permission Set | L5: 005Ro00000G5TJVIA3 | M5: 0PS4O0000009SmrWAE
A6: Aaliyah Reid | B6: areid@probomedical.com | C6: areid@probomedical.com | D6: Standard | E6: Sales Manager | F6: All Account Fields | G6: All_Account_Fields | H6: Regular | I6: FALSE | J6: FALSE | K6: Direct Permission Set | L6: 005Ro00000G5TJVIA3 | M6: 0PS5b000001V1tdGAC
A7: Aaliyah Reid | B7: areid@probomedical.com | C7: areid@probomedical.com | D7: Standard | E7: Sales Manager | F7: Change Account Owner | G7: Change_Account_Owner | H7: Regular | I7: FALSE | J7: FALSE | K7: Direct Permission Set | L7: 005Ro00000G5TJVIA3 | M7: 0PS4O000000OaONWA0
A8: Aaliyah Reid | B8: areid@probomedical.com | C8: areid@probomedical.com | D8: Standard | E8: Sales Manager | F8: Create Item Receipts | G8: Create_Item_Receipts | H8: Regular | I8: FALSE | J8: FALSE | K8: Direct Permission Set | L8: 005Ro00000G5TJVIA3 | M8: 0PS5b000000HmZ0GAK
A9: Aaliyah Reid | B9: areid@probomedical.com | C9: areid@probomedical.com | D9: Standard | E9: Sales Manager | F9: Create new assets | G9: Create_new_assets | H9: Regular | I9: FALSE | J9: FALSE | K9: Direct Permission Set | L9: 005Ro00000G5TJVIA3 | M9: 0PS0B000000b6NDWAY
A10: Aaliyah Reid | B10: areid@probomedical.com | C10: areid@probomedical.com | D10: Standard | E10: Sales Manager | F10: Create Purchasing Opps | G10: Create_Purchasing_Opps | H10: Regular | I10: FALSE | J10: FALSE | K10: Direct Permission Set | L10: 005Ro00000G5TJVIA3 | M10: 0PS4O000000WtjbWAC
A11: Aaliyah Reid | B11: areid@probomedical.com | C11: areid@probomedical.com | D11: Standard | E11: Sales Manager | F11: Creating Price Books | G11: Creating_Price_Books | H11: Regular | I11: FALSE | J11: FALSE | K11: Direct Permission Set | L11: 005Ro00000G5TJVIA3 | M11: 0PS5b000000DkfJGAS
A12: Aaliyah Reid | B12: areid@probomedical.com | C12: areid@probomedical.com | D12: Standard | E12: Sales Manager | F12: Edit Loaner Fields | G12: Edit_Loaner_Fields | H12: Regular | I12: FALSE | J12: FALSE | K12: Direct Permission Set | L12: 005Ro00000G5TJVIA3 | M12: 0PS4O000000zq3SWAQ
A13: Aaliyah Reid | B13: areid@probomedical.com | C13: areid@probomedical.com | D13: Standard | E13: Sales Manager | F13: Endoscopy Test/Repair Permission Set | G13: Endoscopy_Permission_Set | H13: Regular | I13: FALSE | J13: FALSE | K13: Direct Permission Set | L13: 005Ro00000G5TJVIA3 | M13: 0PSRo0000002N5NOAU
... A5728: Phoebe Ding | B5728: pding@probomedical.com | C5728: pding@probomedical.com | D5728: Standard | E5728: Accounting + Sales | F5728: Pandadoc Object Permissions | G5728: Pandadoc_Object_Permissions | H5728: Regular | I5728: FALSE | J5728: FALSE | K5728: Direct Permission Set | L5728: 005Ro000004A0CXIA0 | M5728: 0PS5b000001QEQAGA4
A5729: Platform Integration User | B5729: cloud@00du0000000lakomak | C5729: noreply@salesforce.com | D5729: CloudIntegrationUser | F5729: Chatbot | G5729: sfdc_chatbot | H5729: Session | I5729: FALSE | J5729: FALSE | K5729: Direct Permission Set | L5729: 0054O0000095zVrQAI | M5729: 0PSRo000000D0obOAC
A5730: Platform Integration User | B5730: cloud@00du0000000lakomak | C5730: noreply@salesforce.com | D5730: CloudIntegrationUser | F5730: Constraint Rules Engine Licenseless permission set | G5730: sfdc_nc_constraints_engine_deploy | H5730: Session | I5730: FALSE | J5730: FALSE | K5730: Direct Permission Set | L5730: 0054O0000095zVrQAI | M5730: 0PSRo000000C1oMOAS
A5731: Platform Integration User | B5731: cloud@00du0000000lakomak | C5731: noreply@salesforce.com | D5731: CloudIntegrationUser | F5731: Field Service Integration | G5731: sfdc_fieldservice | H5731: Session | I5731: FALSE | J5731: FALSE | K5731: Direct Permission Set | L5731: 0054O0000095zVrQAI | M5731: 0PSRo0000003vszOAA
A5732: Platform Integration User | B5732: cloud@00du0000000lakomak | C5732: noreply@salesforce.com | D5732: CloudIntegrationUser | F5732: SCRT2 Integration User | G5732: sfdc_scrt2 | H5732: Session | I5732: FALSE | J5732: FALSE | K5732: Direct Permission Set | L5732: 0054O0000095zVrQAI | M5732: 0PSRo0000008PHgOAM
A5733: Platform Integration User | B5733: cloud@00du0000000lakomak | C5733: noreply@salesforce.com | D5733: CloudIntegrationUser | F5733: sfdc.activityplatform | G5733: sfdc_activityplatform | H5733: Session | I5733: FALSE | J5733: FALSE | K5733: Direct Permission Set | L5733: 0054O0000095zVrQAI | M5733: 0PSRo000000GIYrOAO
A5734: Platform Integration User | B5734: cloud@00du0000000lakomak | C5734: noreply@salesforce.com | D5734: CloudIntegrationUser | F5734: sfdc.aiplanner.service.permset | G5734: sfdc_aiplanner_service_permset | H5734: Session | I5734: FALSE | J5734: FALSE | K5734: Direct Permission Set | L5734: 0054O0000095zVrQAI | M5734: 0PSRo000000D0mzOAC
A5735: Preston Allred | B5735: pallred@probomedical.com | C5735: pallred@probomedical.com | D5735: Standard | E5735: Shipping | F5735: Asset and Product Analytics Modify All | G5735: Asset_and_Product_Analytics_Modify_All | H5735: Regular | I5735: FALSE | J5735: FALSE | K5735: Direct Permission Set | L5735: 005Ro00000CBzR3IAL | M5735: 0PSRo000000FMcvOAG
A5736: Preston Allred | B5736: pallred@probomedical.com | C5736: pallred@probomedical.com | D5736: Standard | E5736: Shipping | F5736: Asset2- Review Status | G5736: Asset2_Review_Status | H5736: Regular | I5736: FALSE | J5736: FALSE | K5736: Direct Permission Set | L5736: 005Ro00000CBzR3IAL | M5736: 0PS4O000000zpzzWAA
A5737: Preston Allred | B5737: pallred@probomedical.com | C5737: pallred@probomedical.com | D5737: Standard | E5737: Shipping | F5737: Create and Edit Purchasing Returns | G5737: Create_and_Edit_Purchasing_Returns | H5737: Regular | I5737: FALSE | J5737: FALSE | K5737: Direct Permission Set | L5737: 005Ro00000CBzR3IAL | M5737: 0PSRo0000007CSfOAM
A5738: Preston Allred | B5738: pallred@probomedical.com | C5738: pallred@probomedical.com | D5738: Standard | E5738: Shipping | F5738: Field Service Dispatcher License | G5738: FSL_Dispatcher_License | H5738: Regular | I5738: FALSE | J5738: FALSE | K5738: Direct Permission Set | L5738: 005Ro00000CBzR3IAL | M5738: 0PSRo0000003wnSOAQ
A5739: Preston Allred | B5739: pallred@probomedical.com | C5739: pallred@probomedical.com | D5739: Standard | E5739: Shipping | F5739: Functional Rating for Parts | G5739: Functional_Rating_for_Parts | H5739: Regular | I5739: FALSE | J5739: FALSE | K5739: Direct Permission Set | L5739: 005Ro00000CBzR3IAL | M5739: 0PS4O000000Wta0WAC
A5740: Preston Allred | B5740: pallred@probomedical.com | C5740: pallred@probomedical.com | D5740: Standard | E5740: Shipping | F5740: Location Unlocked | G5740: Location_Unlocked | H5740: Regular | I5740: FALSE | J5740: FALSE | K5740: Direct Permission Set | L5740: 005Ro00000CBzR3IAL | M5740: 0PS4O000000WuOKWA0
A5741: Preston Allred | B5741: pallred@probomedical.com | C5741: pallred@probomedical.com | D5741: Standard | E5741: Shipping | F5741: Manage Assets | G5741: Manage_Assets | H5741: Regular | I5741: FALSE | J5741: FALSE | K5741: Direct Permission Set | L5741: 005Ro00000CBzR3IAL | M5741: 0PS0B000000zmzOWAQ
A5742: Preston Allred | B5742: pallred@probomedical.com | C5742: pallred@probomedical.com | D5742: Standard | E5742: Shipping | F5742: Print Shipping Checklist Button | G5742: Print_Shipping_Checklist_Button | H5742: Regular | I5742: FALSE | J5742: FALSE | K5742: Direct Permission Set | L5742: 005Ro00000CBzR3IAL | M5742: 0PS4O0000009Sf7WAE
A5743: Preston Allred | B5743: pallred@probomedical.com | C5743: pallred@probomedical.com | D5743: Standard | E5743: Shipping | F5743: Shipping Account Number - Opps | G5743: Shipping_Account_Number_Opps | H5743: Regular | I5743: FALSE | J5743: FALSE | K5743: Direct Permission Set | L5743: 005Ro00000CBzR3IAL | M5743: 0PS5b000000HiSwGAK
A5744: Preston Allred | B5744: pallred@probomedical.com | C5744: pallred@probomedical.com | D5744: Standard | E5744: Shipping | F5744: Shipping Cost | G5744: Shipping_Cost | H5744: Regular | I5744: FALSE | J5744: FALSE | K5744: Direct Permission Set | L5744: 005Ro00000CBzR3IAL | M5744: 0PS4O0000009WeiWAE
A5745: Preston Allred | B5745: pallred@probomedical.com | C5745: pallred@probomedical.com | D5745: Standard | E5745: Shipping | F5745: Shipping Team | G5745: Shipping_Team | H5745: Regular | I5745: FALSE | J5745: FALSE | K5745: Direct Permission Set | L5745: 005Ro00000CBzR3IAL | M5745: 0PS5b000000HiFEGA0
A5746: Preston Allred | B5746: pallred@probomedical.com | C5746: pallred@probomedical.com | D5746: Standard | E5746: Shipping | F5746: Shipping/Receiving | G5746: Shipping_Receiving | H5746: Regular | I5746: FALSE | J5746: FALSE | K5746: Direct Permission Set | L5746: 005Ro00000CBzR3IAL | M5746: 0PS0B000000b6NmWAI
... A7222: ZoomInfoAdmin | B7222: zoominfoadmin@probomedical.com | C7222: sdodd@probomedical.com | D7222: Standard | E7222: System Administrator Custom | F7222: Waive MFA | G7222: Waive_MFA | H7222: Regular | I7222: FALSE | J7222: FALSE | K7222: Direct Permission Set | L7222: 005Ro00000FaiLFIAZ | M7222: 0PSRo000000815NOAQ
